
# Created by Ruins mod version 17.2 Ingame Parser
# authoring Player: RCalosena

# TEMPLATE PARAMETER SETTINGS:
#
# criterion expression specifying mod ids required to load template
# may include plus (AND), minus (AND NOT), comma (OR), and parentheses
# all required mods listed must be present; no prohibited mods can be
requiredMods=
#
# likelihood this template will be chosen relative to all others
# e.g., a weight=6 template is chosen 3X as often as one with weight=2
weight=6
#
# list of dimensions in which this template may spawn, even if generic
# one or more dimension names, separated by commas (blank = all)
dimensionsToSpawnIn=
#
# list of other biomes in which this template may spawn
# biome corresponding to directory is always assumed, listed or not
# generic templates should leave this list empty
biomesToSpawnIn=the_beneath
#
# criterion expression specifying types of biome where template spawns
# this is in addition to those explicitly listed as biomesToSpawnIn
# generic templates should leave this list empty
biomeTypesToSpawnIn=
#
# list of biomes in which this template may not spawn
# takes precedence over biomeTypesToSpawnIn, but NOT biomesToSpawnIn
# should be empty if biomeTypesToSpawnIn is empty
biomesToNotSpawnIn=
#
# depth template is pushed down into the surface when built
# offset is min/max range of random additional bury depth
embed_into_distance=1
random_height_offset=0,0
#
# whitelist/blacklist of block types on which template may be built
# specify one, not both; leave the other empty (both empty = allow all)
acceptable_target_blocks= minecraft:stone
unacceptable_target_blocks=flowing_water,water,flowing_lava,lava
#
# size of template (#layers, #rows per layer, #blocks per row)
dimensions=11,15,15
#
# max number of missing blocks allowed in surface beneath template
allowable_overhang=0
#
# depth/height limit affected by terrain leveling
# also maximum bumpiness tolerated in surface beneath template
max_leveling=2
#
# padding applied to all sides of template horizontal footprint
# expands area affected by terrain leveling (-1 = no leveling)
leveling_buffer=0
#
# do not rotate template randomly when built (1 = no rotation)
preventRotation=0
#
# treat water/lava blocks as air and protect them from rule0 (1 = yes)
preserve_water=0
preserve_lava=0
#
# minimum distance this template must have from instances of itself
uniqueMinDistance=0
#
# min/max distances this template can be from world spawn (0 = no limit)
# only applies to overworld--i.e., dimension 0
spawnMinDistance=0
spawnMaxDistance=0
#
# other template built nearby whenever this one is
# syntax: <name>;<relativeX>;<maxYdifference>;<relativeZ>[;<chance>]
# may be used more than once to specify multiple neighbors
adjoining_template=

rule1=0,100,minecraft:stone-0
rule2=0,100,nyx:meteor_rock-0
rule3=0,100,metallurgy:mithril_ore-0
rule4=0,100,metallurgy:carmot_ore-0
rule5=0,100,metallurgy:atlarus_ore-0
rule6=0,100,minecraft:obsidian-0
rule7=0,100,metallurgy:adamantine_ore-0

layer
0,0,0,0,1,1,1,1,1,1,1,0,0,0,0
0,0,1,1,1,1,1,1,1,1,1,1,1,0,0
0,1,1,1,1,1,1,1,1,1,1,1,1,1,0
0,1,1,1,1,1,1,1,1,1,1,1,1,1,0
1,1,1,1,1,1,1,1,1,1,1,1,1,1,1
1,1,1,1,1,1,1,1,1,1,1,1,1,1,1
1,1,1,1,1,1,1,1,1,1,1,1,1,1,1
1,1,1,1,1,1,1,2,1,1,1,1,1,1,1
1,1,1,1,1,1,1,1,1,1,1,1,1,1,1
1,1,1,1,1,1,1,1,1,1,1,1,1,1,1
1,1,1,1,1,1,1,1,1,1,1,1,1,1,1
0,1,1,1,1,1,1,1,1,1,1,1,1,1,0
0,1,1,1,1,1,1,1,1,1,1,1,1,1,0
0,0,1,1,1,1,1,1,1,1,1,1,1,0,0
0,0,0,0,1,1,1,1,1,1,1,0,0,0,0
endlayer

layer
0,0,0,0,0,0,1,1,1,0,0,0,0,0,0
0,0,0,0,1,1,1,1,1,1,1,0,0,0,0
0,0,1,1,1,1,1,1,1,1,1,1,1,0,0
0,0,1,1,1,1,1,1,1,1,1,1,1,0,0
0,1,1,1,1,1,1,1,1,1,1,1,1,1,0
0,1,1,1,1,1,1,2,1,1,1,1,1,1,0
1,1,1,1,1,1,2,2,2,1,1,1,1,1,1
1,1,1,1,1,2,2,3,2,2,1,1,1,1,1
1,1,1,1,1,1,2,2,2,1,1,1,1,1,1
0,1,1,1,1,1,1,2,1,1,1,1,1,1,0
0,1,1,1,1,1,1,1,1,1,1,1,1,1,0
0,0,1,1,1,1,1,1,1,1,1,1,1,0,0
0,0,1,1,1,1,1,1,1,1,1,1,1,0,0
0,0,0,0,1,1,1,1,1,1,1,0,0,0,0
0,0,0,0,0,0,1,1,1,0,0,0,0,0,0
endlayer

layer
0,0,0,0,0,0,0,0,0,0,0,0,0,0,0
0,0,0,0,0,0,1,1,1,0,0,0,0,0,0
0,0,0,1,1,1,1,1,1,1,0,0,0,0,0
0,0,1,1,1,1,1,1,1,1,1,1,0,0,0
0,0,1,1,1,1,1,2,1,1,1,1,0,0,0
0,0,1,1,1,2,2,4,2,2,1,1,1,0,0
0,1,1,1,1,2,3,5,5,2,1,1,1,1,0
0,1,1,1,2,3,3,3,3,3,2,1,1,1,0
0,1,1,1,1,2,4,4,4,2,1,1,1,1,0
0,0,1,1,1,2,2,4,2,2,1,1,1,0,0
0,0,1,1,1,1,1,2,1,1,1,1,1,0,0
0,0,1,1,1,1,1,1,1,1,1,1,1,0,0
0,0,0,1,1,1,1,1,1,1,1,1,0,0,0
0,0,0,0,0,0,1,1,1,0,0,0,0,0,0
0,0,0,0,0,0,0,0,0,0,0,0,0,0,0
endlayer

layer
0,0,0,0,0,0,0,0,0,0,0,0,0,0,0
0,0,0,0,0,0,0,6,0,0,0,0,0,0,0
0,0,0,0,0,0,6,2,2,0,0,0,0,0,0
0,0,0,0,0,2,2,2,2,2,0,0,0,0,0
0,0,0,2,2,2,2,4,2,2,6,0,0,0,0
0,0,0,2,2,5,4,3,4,4,6,0,0,0,0
0,0,2,2,2,5,5,3,5,5,2,6,0,0,0
0,0,2,2,7,5,7,7,7,7,7,2,2,0,0
0,0,2,2,2,4,3,3,4,4,2,2,0,0,0
0,0,0,0,2,4,4,4,4,4,2,0,0,0,0
0,0,0,0,6,2,2,4,2,2,2,0,0,0,0
0,0,0,6,6,6,2,2,2,2,0,0,0,0,0
0,0,0,0,0,0,0,2,2,0,0,0,0,0,0
0,0,0,0,0,0,0,2,0,0,0,0,0,0,0
0,0,0,0,0,0,0,0,0,0,0,0,0,0,0
endlayer

layer
0,0,0,0,0,0,0,0,0,0,0,0,0,0,0
0,0,0,0,0,0,0,0,0,0,0,0,0,0,0
0,0,0,0,0,0,6,2,6,0,0,0,0,0,0
0,0,0,0,0,2,2,4,2,2,0,0,0,0,0
0,0,0,0,2,4,4,3,4,4,6,0,0,0,0
0,0,0,2,4,4,7,7,3,3,6,0,0,0,0
0,0,0,2,4,4,4,7,3,3,5,2,0,0,0
0,0,2,7,5,5,5,5,5,5,7,7,2,0,0
0,0,0,2,7,7,7,7,7,5,5,2,0,0,0
0,0,0,2,7,7,3,3,7,7,7,2,0,0,0
0,0,0,0,2,7,3,3,7,7,2,0,0,0,0
0,0,0,0,0,2,2,3,2,2,0,0,0,0,0
0,0,0,0,0,0,0,2,0,0,0,0,0,0,0
0,0,0,0,0,0,0,0,0,0,0,0,0,0,0
0,0,0,0,0,0,0,0,0,0,0,0,0,0,0
endlayer

layer
0,0,0,0,0,0,0,0,0,0,0,0,0,0,0
0,0,0,0,0,0,0,0,0,0,0,0,0,0,0
0,0,0,0,0,0,2,2,2,0,0,0,0,0,0
0,0,0,0,0,2,2,3,2,2,0,0,0,0,0
0,0,0,0,2,3,7,7,3,3,2,0,0,0,0
0,0,0,2,7,7,7,5,7,5,3,6,0,0,0
0,0,2,2,5,5,3,3,4,3,3,2,2,0,0
0,0,2,5,3,3,3,3,3,3,5,7,2,0,0
0,0,2,2,4,4,4,4,5,4,4,2,2,0,0
0,0,0,2,0,5,5,5,5,5,5,2,0,0,0
0,0,0,0,2,5,7,7,7,7,2,0,0,0,0
0,0,0,0,0,2,2,3,2,2,0,0,0,0,0
0,0,0,0,0,0,2,2,2,0,0,0,0,0,0
0,0,0,0,0,0,0,0,0,0,0,0,0,0,0
0,0,0,0,0,0,0,0,0,0,0,0,0,0,0
endlayer

layer
0,0,0,0,0,0,0,0,0,0,0,0,0,0,0
0,0,0,0,0,0,0,0,0,0,0,0,0,0,0
0,0,0,0,0,0,0,2,0,0,0,0,0,0,0
0,0,0,0,0,2,2,7,2,2,0,0,0,0,0
0,0,0,0,6,7,7,5,7,7,2,0,0,0,0
0,0,0,6,5,5,5,3,5,5,5,2,0,0,0
0,0,0,2,5,5,3,4,4,3,5,2,0,0,0
0,0,2,0,4,4,4,4,4,3,3,7,2,0,0
0,0,0,6,4,4,4,4,3,4,4,2,0,0,0
0,0,0,2,0,3,3,3,3,5,5,2,0,0,0
0,0,0,0,2,5,5,5,7,7,2,0,0,0,0
0,0,0,0,0,2,2,7,2,2,0,0,0,0,0
0,0,0,0,0,0,0,2,0,0,0,0,0,0,0
0,0,0,0,0,0,0,0,0,0,0,0,0,0,0
0,0,0,0,0,0,0,0,0,0,0,0,0,0,0
endlayer

layer
0,0,0,0,0,0,0,0,0,0,0,0,0,0,0
0,0,0,0,0,0,0,0,0,0,0,0,0,0,0
0,0,0,0,0,0,0,0,0,0,0,0,0,0,0
0,0,0,0,0,0,0,2,0,0,0,0,0,0,0
0,0,0,0,0,2,2,3,2,2,0,0,0,0,0
0,0,0,0,2,4,4,3,3,3,2,0,0,0,0
0,0,0,6,2,4,5,3,7,7,2,0,0,0,0
0,0,0,6,7,7,5,7,7,7,7,2,0,0,0
0,0,0,0,2,4,4,3,3,4,2,0,0,0,0
0,0,0,0,2,3,3,3,5,5,2,0,0,0,0
0,0,0,0,0,2,2,7,2,2,0,0,0,0,0
0,0,0,0,0,0,0,2,0,0,0,0,0,0,0
0,0,0,0,0,0,0,0,0,0,0,0,0,0,0
0,0,0,0,0,0,0,0,0,0,0,0,0,0,0
0,0,0,0,0,0,0,0,0,0,0,0,0,0,0
endlayer

layer
0,0,0,0,0,0,0,0,0,0,0,0,0,0,0
0,0,0,0,0,0,0,0,0,0,0,0,0,0,0
0,0,0,0,0,0,0,0,0,0,0,0,0,0,0
0,0,0,0,0,0,0,0,0,0,0,0,0,0,0
0,0,0,0,0,0,0,2,0,0,0,0,0,0,0
0,0,0,0,0,2,2,7,2,2,0,0,0,0,0
0,0,0,0,0,2,5,5,5,2,0,0,0,0,0
0,0,0,0,2,5,5,7,5,7,2,0,0,0,0
0,0,0,0,0,2,4,3,3,2,0,0,0,0,0
0,0,0,0,0,2,2,3,2,2,0,0,0,0,0
0,0,0,0,0,0,0,2,0,0,0,0,0,0,0
0,0,0,0,0,0,0,0,0,0,0,0,0,0,0
0,0,0,0,0,0,0,0,0,0,0,0,0,0,0
0,0,0,0,0,0,0,0,0,0,0,0,0,0,0
0,0,0,0,0,0,0,0,0,0,0,0,0,0,0
endlayer

layer
0,0,0,0,0,0,0,0,0,0,0,0,0,0,0
0,0,0,0,0,0,0,0,0,0,0,0,0,0,0
0,0,0,0,0,0,0,0,0,0,0,0,0,0,0
0,0,0,0,0,0,0,0,0,0,0,0,0,0,0
0,0,0,0,0,0,0,0,0,0,0,0,0,0,0
0,0,0,0,0,0,0,2,0,0,0,0,0,0,0
0,0,0,0,0,0,2,2,2,0,0,0,0,0,0
0,0,0,0,0,2,2,4,2,2,0,0,0,0,0
0,0,0,0,0,0,2,2,2,0,0,0,0,0,0
0,0,0,0,0,0,0,2,0,0,0,0,0,0,0
0,0,0,0,0,0,0,0,0,0,0,0,0,0,0
0,0,0,0,0,0,0,0,0,0,0,0,0,0,0
0,0,0,0,0,0,0,0,0,0,0,0,0,0,0
0,0,0,0,0,0,0,0,0,0,0,0,0,0,0
0,0,0,0,0,0,0,0,0,0,0,0,0,0,0
endlayer

layer
0,0,0,0,0,0,0,0,0,0,0,0,0,0,0
0,0,0,0,0,0,0,0,0,0,0,0,0,0,0
0,0,0,0,0,0,0,0,0,0,0,0,0,0,0
0,0,0,0,0,0,0,0,0,0,0,0,0,0,0
0,0,0,0,0,0,0,0,0,0,0,0,0,0,0
0,0,0,0,0,0,0,0,0,0,0,0,0,0,0
0,0,0,0,0,0,0,0,0,0,0,0,0,0,0
0,0,0,0,0,0,0,2,0,0,0,0,0,0,0
0,0,0,0,0,0,0,0,0,0,0,0,0,0,0
0,0,0,0,0,0,0,0,0,0,0,0,0,0,0
0,0,0,0,0,0,0,0,0,0,0,0,0,0,0
0,0,0,0,0,0,0,0,0,0,0,0,0,0,0
0,0,0,0,0,0,0,0,0,0,0,0,0,0,0
0,0,0,0,0,0,0,0,0,0,0,0,0,0,0
0,0,0,0,0,0,0,0,0,0,0,0,0,0,0
endlayer

